<mujoco model="ur5e">
  <default>
    <joint axis="0 1 0" range="-6.28319 6.28319" />
    <position ctrlrange="-6.2831 6.2831" />
    
    <default class="visual_tool">
      <geom type="capsule" contype="0" conaffinity="0" size=".0025 .001" group="2" />
    </default>
    <default class="collision_tool">
      <geom type="capsule" size=".0025 .001" group="3" />
    </default>
    <default class="tool_ball_joint">
      <joint type="ball" range="0 6.28319" stiffness="0.1610809834228603" damping="0.018688155476703796" />
    </default>
    

    <default class="visual_arm">
      <geom type="mesh" contype="0" conaffinity="0" group="2" />
    </default>
    <default class="collision_arm">
      <geom type="capsule" group="3" />
      <default class="eef_collision">
        <geom type="cylinder" />
      </default>
    </default>
    <site size="0.001" rgba="0.5 0.5 0.5 0.3" group="4" />

    
    <default class="size3">
      <joint armature="0.1" damping="300" />
      <position kp="3500" forcerange="-150 150" ctrllimited="true" />
      <default class="size3_limited">
        <joint range="-3.1415 3.1415" />
        <position ctrlrange="-3.1415 3.1415" ctrllimited="true" />
      </default>
    </default>
    <default class="size1">
      <joint armature="0.1" damping="15" />
      <position kp="3000" forcerange="-28 28" />
    </default>

    <default class="2f85">
        <mesh scale="0.001 0.001 0.001" />
        <general biastype="affine" />

        <joint axis="1 0 0" />
        <default class="driver">
            <joint range="0 0.8" armature="0.005" damping="0.1" solimplimit="0.95 0.99 0.001" solreflimit="0.005 1" />
        </default>
        <default class="follower">
            <joint range="-0.872664 0.872664" pos="0 -0.018 0.0065" solimplimit="0.95 0.99 0.001" solreflimit="0.005 1" />
        </default>
        <default class="spring_link">
            <joint range="-0.29670597283 0.8" stiffness="0.05" springref="2.62" damping="0.00125" />
        </default>
        <default class="coupler">
            <joint range="-1.57 0" solimplimit="0.95 0.99 0.001" solreflimit="0.005 1" />
        </default>

        <default class="visual">
            <geom type="mesh" contype="0" conaffinity="0" group="2" />
        </default>
        <default class="collision">
            <geom type="mesh" group="3" />
            <default class="pad_box1">
            <geom mass="0" type="box" pos="0 -0.0026 0.028125" size="0.011 0.004 0.009375" friction="0.7" solimp="0.95 0.99 0.001" solref="0.004 1" priority="1" rgba="0.55 0.55 0.55 1" />
            </default>
            <default class="pad_box2">
            <geom mass="0" type="box" pos="0 -0.0026 0.009375" size="0.011 0.004 0.009375" friction="0.6" solimp="0.95 0.99 0.001" solref="0.004 1" priority="1" rgba="0.45 0.45 0.45 1" />
            </default>
        </default>
    </default>
  </default>

  <asset>
    <material name="black" specular="0.5" shininess="0.25" rgba="0.033 0.033 0.033 1" />
    <material name="jointgray" specular="0.5" shininess="0.25" rgba="0.278 0.278 0.278 1" />
    <material name="linkgray" specular="0.5" shininess="0.25" rgba="0.82 0.82 0.82 1" />
    <material name="urblue" specular="0.5" shininess="0.25" rgba="0.49 0.678 0.8 1" />

    <mesh file="base_0.obj" />
    <mesh file="base_1.obj" />
    <mesh file="shoulder_0.obj" />
    <mesh file="shoulder_1.obj" />
    <mesh file="shoulder_2.obj" />
    <mesh file="upperarm_0.obj" />
    <mesh file="upperarm_1.obj" />
    <mesh file="upperarm_2.obj" />
    <mesh file="upperarm_3.obj" />
    <mesh file="forearm_0.obj" />
    <mesh file="forearm_1.obj" />
    <mesh file="forearm_2.obj" />
    <mesh file="forearm_3.obj" />
    <mesh file="wrist1_0.obj" />
    <mesh file="wrist1_1.obj" />
    <mesh file="wrist1_2.obj" />
    <mesh file="wrist2_0.obj" />
    <mesh file="wrist2_1.obj" />
    <mesh file="wrist2_2.obj" />
    <mesh file="wrist3.obj" />

    <mesh name="tubetool" file="cube_insertion_tool.stl" />

    <mesh class="2f85" file="base_mount.stl" />
    <mesh class="2f85" file="base2f85.stl" />
    <mesh class="2f85" file="driver.stl" />
    <mesh class="2f85" file="coupler.stl" />
    <mesh class="2f85" file="follower.stl" />
    <mesh class="2f85" file="pad.stl" />
    <mesh class="2f85" file="silicone_pad.stl" />
    <mesh class="2f85" file="spring_link.stl" />

    <material name="metal" rgba="0.58 0.58 0.58 1" />
    <material name="silicone" rgba="0.1882 0.1882 0.1882 1" />
    <material name="gray" rgba="0.4627 0.4627 0.4627 1" />
  </asset>

  <worldbody>
    <light name="spotlight" mode="targetbodycom" target="wrist_2_link" pos="0 -1 2" />
    <body name="OUR_TABLE" pos="0 0 0.435">
        <geom size=".08 .08 .04" pos="0 0 0.4" type="box" />
        <geom size=".04 .04 .435" pos="0 0 0" type="box" />
        <inertial pos="0 0 0" mass="1000" diaginertia="0 0 0" />
        <body name="base_arm" pos="0 0 0.435">
          <inertial mass="4.0" pos="0 0 0" diaginertia="0.00443333156 0.00443333156 0.0072" />
          <geom mesh="base_0" material="black" class="visual_arm" />
          <geom mesh="base_1" material="jointgray" class="visual_arm" />
          <body name="shoulder_link" pos="0 0 0.163">
            <inertial mass="3.7" pos="0 0 0" diaginertia="0.0102675 0.0102675 0.00666" />
            <joint name="shoulder_pan_joint" class="size3" axis="0 0 1" />
            <geom mesh="shoulder_0" material="urblue" class="visual_arm" />
            <geom mesh="shoulder_1" material="black" class="visual_arm" />
            <geom mesh="shoulder_2" material="jointgray" class="visual_arm" />
            <geom class="collision_arm" size="0.06 0.06" pos="0 0 -0.04" />
            <body name="upper_arm_link" pos="0 0.138 0" quat="1 0 1 0">
              <inertial mass="8.393" pos="0 0 0.2125" diaginertia="0.133886 0.133886 0.0151074" />
              <joint name="shoulder_lift_joint" class="size3" />
              <geom mesh="upperarm_0" material="linkgray" class="visual_arm" />
              <geom mesh="upperarm_1" material="black" class="visual_arm" />
              <geom mesh="upperarm_2" material="jointgray" class="visual_arm" />
              <geom mesh="upperarm_3" material="urblue" class="visual_arm" />
              <geom class="collision_arm" pos="0 -0.04 0" quat="1 1 0 0" size="0.06 0.06" />
              <geom class="collision_arm" size="0.05 0.2" pos="0 0 0.2" />
              <body name="forearm_link" pos="0 -0.131 0.425">
                <inertial mass="2.275" pos="0 0 0.196" diaginertia="0.0311796 0.0311796 0.004095" />
                <joint name="elbow_joint" class="size3_limited" />
                <geom mesh="forearm_0" material="urblue" class="visual_arm" />
                <geom mesh="forearm_1" material="linkgray" class="visual_arm" />
                <geom mesh="forearm_2" material="black" class="visual_arm" />
                <geom mesh="forearm_3" material="jointgray" class="visual_arm" />
                <geom class="collision_arm" pos="0 0.08 0" quat="1 1 0 0" size="0.055 0.06" />
                <geom class="collision_arm" size="0.038 0.19" pos="0 0 0.2" />
                <body name="wrist_1_link" pos="0 0 0.392" quat="1 0 1 0">
                  <inertial mass="1.219" pos="0 0.127 0" diaginertia="0.0025599 0.0025599 0.0021942" />
                  <joint name="wrist_1_joint" class="size1" />
                  <geom mesh="wrist1_0" material="black" class="visual_arm" />
                  <geom mesh="wrist1_1" material="urblue" class="visual_arm" />
                  <geom mesh="wrist1_2" material="jointgray" class="visual_arm" />
                  <geom class="collision_arm" pos="0 0.05 0" quat="1 1 0 0" size="0.04 0.07" />
                  <body name="wrist_2_link" pos="0 0.127 0">
                    <inertial mass="1.219" pos="0 0 0.1" diaginertia="0.0025599 0.0025599 0.0021942" />
                    <joint name="wrist_2_joint" axis="0 0 1" class="size1" />
                    <geom mesh="wrist2_0" material="black" class="visual_arm" />
                    <geom mesh="wrist2_1" material="urblue" class="visual_arm" />
                    <geom mesh="wrist2_2" material="jointgray" class="visual_arm" />
                    <geom class="collision_arm" size="0.04 0.06" pos="0 0 0.04" />
                    <geom class="collision_arm" pos="0 0.02 0.1" quat="1 1 0 0" size="0.04 0.04" />
                    <body name="wrist_3_link" pos="0 0 0.1">
                      <inertial mass="0.1889" pos="0 0.0771683 0" quat="1 0 0 1" diaginertia="0.000132134 9.90863e-05 9.90863e-05" />
                      <joint name="wrist_3_joint" class="size1" />
                      <geom material="linkgray" mesh="wrist3" class="visual_arm" />
                      <geom class="eef_collision" pos="0 0.08 0" quat="1 1 0 0" size="0.04 0.02" />
                      <site name="attachment_site" pos="0 0.1 0" quat="1 1 0 0" />
                      
                      <body name="base_mount" pos="0 0.1 -0.0005" quat="0.707107 -0.707107 0 0" childclass="2f85">
                          <geom class="visual" mesh="base_mount" material="black" />
                          <geom class="collision" mesh="base_mount" />
                          <site name="ee_site" pos="0 0 0.06" size="0.005 0.005 0.005" type="sphere" rgba="0.3 0.2 0.1 1" />
                          
                                                        
                          <body name="cylinder_obj" pos="0 0 0.15"> 
                                <geom class="collision_tool" />
                                
                                <geom class="visual_tool" rgba="1 0.5 0.5 1" />
                                <joint class="tool_ball_joint" />
                                <body name="cylinder_obj1" pos="0 0 0.005">
                                    <geom class="collision_tool" />
                                    <geom class="visual_tool" rgba="0 0.5 0.5 1" />
                                    <joint class="tool_ball_joint" />
                                    <body name="cylinder_obj2" pos="0 0 0.005">
                                        <geom class="collision_tool" />
                                        <geom class="visual_tool" rgba="0 0.5 0.5 1" />
                                        <joint class="tool_ball_joint" />
                                        <body name="cylinder_obj3" pos="0 0 0.005">
                                            <geom class="collision_tool" />
                                            <geom class="visual_tool" rgba="0 0.5 0.5 1" />
                                            <joint class="tool_ball_joint" />
                                            <body name="cylinder_obj4" pos="0 0 0.005">
                                                <geom class="collision_tool" />
                                                <geom class="visual_tool" rgba="0 0.5 0.5 1" />
                                                <joint class="tool_ball_joint" />
                                                <body name="cylinder_obj5" pos="0 0 0.005">
                                                    <geom class="collision_tool" />
                                                    <geom class="visual_tool" rgba="0 0.5 0.5 1" />
                                                    <joint class="tool_ball_joint" />
                                                    <body name="cylinder_obj6" pos="0 0 0.005">
                                                        <geom class="collision_tool" />
                                                        <geom class="visual_tool" rgba="0 0.5 0.5 1" />
                                                        <joint class="tool_ball_joint" />
                                                        <body name="cylinder_obj7" pos="0 0 0.005">
                                                            <geom class="collision_tool" />
                                                            <geom class="visual_tool" rgba="0 0.5 0.5 1" />
                                                            <joint class="tool_ball_joint" />
                                                            <body name="cylinder_obj8" pos="0 0 0.005">
                                                                <geom class="collision_tool" />
                                                                <geom class="visual_tool" rgba="0 0.5 0.5 1" />
                                                                <joint class="tool_ball_joint" />
                                                                <body name="cylinder_obj9" pos="0 0 0.005">
                                                                    <geom class="collision_tool" />
                                                                    <geom class="visual_tool" rgba="0 0.5 0.5 1" />
                                                                    <joint class="tool_ball_joint" />
                                                                    <body name="cylinder_obj10" pos="0 0 0.005">
                                                                        <geom class="collision_tool" />
                                                                        <geom class="visual_tool" rgba="0 0.5 0.5 1" />
                                                                        <joint class="tool_ball_joint" />
                                                                        <body name="cylinder_obj11" pos="0 0 0.005">
                                                                            <geom class="collision_tool" />
                                                                            <geom class="visual_tool" rgba="0 0.5 0.5 1" />
                                                                            <joint class="tool_ball_joint" />
                                                                            <body name="cylinder_obj12" pos="0 0 0.005">
                                                                                <geom class="collision_tool" />
                                                                                <geom class="visual_tool" rgba="0 0.5 0.5 1" />
                                                                                <joint class="tool_ball_joint" />
                                                                                <body name="cylinder_obj13" pos="0 0 0.005">
                                                                                    <geom class="collision_tool" />
                                                                                    <geom class="visual_tool" rgba="0 0.5 0.5 1" />
                                                                                    <joint class="tool_ball_joint" />
                                                                                    <body name="cylinder_obj14" pos="0 0 0.005">
                                                                                        <geom class="collision_tool" />
                                                                                        <geom class="visual_tool" rgba="0 0.5 0.5 1" />
                                                                                        <joint class="tool_ball_joint" />
                                                                                        <body name="cylinder_obj15" pos="0 0 0.005">
                                                                                            <geom class="collision_tool" />
                                                                                            <geom class="visual_tool" rgba="0 0.5 0.5 1" />

                                                                                            <site name="obj_bottom" type="sphere" size=".001 .001 .001" pos="0 0 0" quat="1 0 0 0" />
                                                                                        </body>
                                                                                    </body>
                                                                                </body>
                                                                            </body>
                                                                        </body>
                                                                    </body>
                                                                </body>
                                                            </body>
                                                        </body>
                                                    </body>
                                                </body>
                                            </body>
                                        </body>
                                    </body>
                                </body>
                          </body>
                      </body>
                    </body>
                  </body>
                </body>
              </body>
            </body>
          </body>
        </body>
      </body>
  </worldbody>

    <actuator>
        <position class="size3" name="shoulder_pan" joint="shoulder_pan_joint" />
        <position class="size3" name="shoulder_lift" joint="shoulder_lift_joint" />
        <position class="size3_limited" name="elbow" joint="elbow_joint" />
        <position class="size1" name="wrist_1" joint="wrist_1_joint" />
        <position class="size1" name="wrist_2" joint="wrist_2_joint" />
        <position class="size1" name="wrist_3" joint="wrist_3_joint" />
        
    </actuator>
    <contact>
        

        <exclude body1="cylinder_obj" body2="cylinder_obj1" />
        <exclude body1="cylinder_obj1" body2="cylinder_obj2" />
        <exclude body1="cylinder_obj3" body2="cylinder_obj2" />
        <exclude body1="cylinder_obj3" body2="cylinder_obj4" />
        <exclude body1="cylinder_obj5" body2="cylinder_obj4" />
        <exclude body1="cylinder_obj5" body2="cylinder_obj6" />
        <exclude body1="cylinder_obj7" body2="cylinder_obj6" />
        <exclude body1="cylinder_obj7" body2="cylinder_obj8" />
        <exclude body1="cylinder_obj9" body2="cylinder_obj8" />
        <exclude body1="cylinder_obj10" body2="cylinder_obj10" />
        <exclude body1="cylinder_obj11" body2="cylinder_obj10" />
        <exclude body1="cylinder_obj11" body2="cylinder_obj12" />
        <exclude body1="cylinder_obj13" body2="cylinder_obj12" />
        <exclude body1="cylinder_obj13" body2="cylinder_obj14" />
        <exclude body1="cylinder_obj15" body2="cylinder_obj14" />

    </contact>
    
    
    <sensor>
        <force name="ee_force_sensor" site="ee_site" />
        <torque name="ee_torque_sensor" site="ee_site" />
    </sensor>




</mujoco>