<mujoco model="ur5e">
  <default>
<!--    <joint axis="0 1 0" range="-6.28319 6.28319" />-->
<!--    <position ctrlrange="-6.2831 6.2831" />-->

    <default class="visual_tool">
      <geom type="capsule" contype="0" conaffinity="0" size=".0025 .001" group="2" />
    </default>
    <default class="collision_tool">
      <geom type="capsule" size=".0025 .001" group="3" />
    </default>
    <default class="tool_ball_joint">
      <joint type="ball" range="0 6.28319" stiffness="0.1618890981497937" damping="0.08587470841787867" />
    </default>


    <default class="visual_arm">
      <geom type="mesh" contype="0" conaffinity="0" group="2" />
    </default>
    <default class="collision_arm">
      <geom type="capsule" group="3" />
      <default class="eef_collision">
        <geom type="cylinder" />
      </default>
    </default>
    <site size="0.001" rgba="0.5 0.5 0.5 0.3" group="4" />


    <default class="size3">
      <joint armature="0.1" damping="300" />
      <position kp="3500" forcerange="-150 150" ctrllimited="true" />
      <default class="size3_limited">
        <joint range="-3.1415 3.1415" />
        <position ctrlrange="-3.1415 3.1415" ctrllimited="true" />
      </default>
    </default>
    <default class="size1">
      <joint armature="0.1" damping="15" />
      <position kp="3000" forcerange="-28 28" />
    </default>

    <default class="2f85">
        <mesh scale="0.001 0.001 0.001" />
        <general biastype="affine" />

        <joint axis="1 0 0" />
        <default class="driver">
            <joint range="0 0.8" armature="0.005" damping="0.1" solimplimit="0.95 0.99 0.001" solreflimit="0.005 1" />
        </default>
        <default class="follower">
            <joint range="-0.872664 0.872664" pos="0 -0.018 0.0065" solimplimit="0.95 0.99 0.001" solreflimit="0.005 1" />
        </default>
        <default class="spring_link">
            <joint range="-0.29670597283 0.8" stiffness="0.05" springref="2.62" damping="0.00125" />
        </default>
        <default class="coupler">
            <joint range="-1.57 0" solimplimit="0.95 0.99 0.001" solreflimit="0.005 1" />
        </default>

        <default class="visual">
            <geom type="mesh" contype="0" conaffinity="0" group="2" />
        </default>
        <default class="collision">
            <geom type="mesh" group="3" />
            <default class="pad_box1">
            <geom mass="0" type="box" pos="0 -0.0026 0.028125" size="0.011 0.004 0.009375" friction="0.7" solimp="0.95 0.99 0.001" solref="0.004 1" priority="1" rgba="0.55 0.55 0.55 1" />
            </default>
            <default class="pad_box2">
            <geom mass="0" type="box" pos="0 -0.0026 0.009375" size="0.011 0.004 0.009375" friction="0.6" solimp="0.95 0.99 0.001" solref="0.004 1" priority="1" rgba="0.45 0.45 0.45 1" />
            </default>
        </default>
    </default>
  </default>

  <asset>
    <material name="black" specular="0.5" shininess="0.25" rgba="0.033 0.033 0.033 1" />
    <material name="jointgray" specular="0.5" shininess="0.25" rgba="0.278 0.278 0.278 1" />
    <material name="linkgray" specular="0.5" shininess="0.25" rgba="0.82 0.82 0.82 1" />
    <material name="urblue" specular="0.5" shininess="0.25" rgba="0.49 0.678 0.8 1" />
    <mesh name="base" file="base.stl" />
    <mesh name="shoulder" file="shoulder.stl" />
    <mesh name="upperarm" file="upperarm.stl" />
    <mesh name="forearm" file="forearm.stl" />
    <mesh name="wrist1" file="wrist1.stl" />
    <mesh name="wrist2" file="wrist2.stl" />
    <mesh name="wrist3" file="wrist3.stl" />
<!--    <mesh file="base_0.obj" />-->
<!--    <mesh file="base_1.obj" />-->
<!--    <mesh file="shoulder_0.obj" />-->
<!--    <mesh file="shoulder_1.obj" />-->
<!--    <mesh file="shoulder_2.obj" />-->
<!--    <mesh file="upperarm_0.obj" />-->
<!--    <mesh file="upperarm_1.obj" />-->
<!--    <mesh file="upperarm_2.obj" />-->
<!--    <mesh file="upperarm_3.obj" />-->
<!--    <mesh file="forearm_0.obj" />-->
<!--    <mesh file="forearm_1.obj" />-->
<!--    <mesh file="forearm_2.obj" />-->
<!--    <mesh file="forearm_3.obj" />-->
<!--    <mesh file="wrist1_0.obj" />-->
<!--    <mesh file="wrist1_1.obj" />-->
<!--    <mesh file="wrist1_2.obj" />-->
<!--    <mesh file="wrist2_0.obj" />-->
<!--    <mesh file="wrist2_1.obj" />-->
<!--    <mesh file="wrist2_2.obj" />-->
<!--    <mesh file="wrist3.obj" />-->

    <mesh name="tubetool" file="cube_insertion_tool.stl" />

    <mesh class="2f85" file="base_mount.stl" />
    <mesh class="2f85" file="base2f85.stl" />
    <mesh class="2f85" file="driver.stl" />
    <mesh class="2f85" file="coupler.stl" />
    <mesh class="2f85" file="follower.stl" />
    <mesh class="2f85" file="pad.stl" />
    <mesh class="2f85" file="silicone_pad.stl" />
    <mesh class="2f85" file="spring_link.stl" />

    <material name="metal" rgba="0.58 0.58 0.58 1" />
    <material name="silicone" rgba="0.1882 0.1882 0.1882 1" />
    <material name="gray" rgba="0.4627 0.4627 0.4627 1" />
  </asset>

  <worldbody>
    <light name="spotlight" mode="targetbodycom" target="wrist_2_link" pos="0 -1 2" />
    <body name="OUR_TABLE" pos="0 0 0.435">
        <geom size=".08 .08 .04" pos="0 0 0.4" type="box" />
        <geom size=".04 .04 .435" pos="0 0 0" type="box" />
        <inertial pos="0 0 0" mass="1000" diaginertia="0 0 0" />
        <body name="base_link" pos="0 0 0.435" quat="0.75 0 0.75">
                <inertial pos="0 0 0" quat="0.5 0.5 -0.5 0.5" mass="4" diaginertia="0.005625 0.00305317 0.00305317" />
                <geom type="mesh"  mesh="base" material="black" class="visual_arm"/>
                <body name="shoulder_link" pos="0 0 0.1530">
                    <inertial pos="0 0 0" mass="3" diaginertia="0.00809316 0.00809316 0.005625" />
                    <joint name="shoulder_pan_joint" class="size3" axis="0 0 1" />
                    <geom type="mesh"  mesh="shoulder" material="urblue" class="visual_arm"/>
                    <body name="upper_arm_link" pos="0 0.1198 0" quat="0.707107 0 0.707107 0">
                        <inertial pos="0 0 0.121825" mass="3.42" diaginertia="0.0217285 0.0217285 0.00961875" />
                        <joint name="shoulder_lift_joint" class="size3"  axis="0 1 0"/>
                        <geom type="mesh"  mesh="upperarm" material="black" class="visual_arm"/>
                        <body name="forearm_link" pos="0 -0.0925 0.24365">
                            <inertial pos="0 0 0.106625" mass="1.26" diaginertia="0.00654681 0.00654681 0.00354375" />
                            <joint name="elbow_joint" class="size3_limited"  axis="0 1 0"  />
                            <geom type="mesh"  mesh="forearm" material="ur3_mat" conaffinity="0" group="1"/>
                            <body name="wrist_1_link" pos="0 0 0.21325" quat="0.707107 0 0.707107 0">
                                <inertial pos="0 0 0" quat="0.5 0.5 -0.5 0.5" mass="0.8" diaginertia="0.00225 0.002085 0.002085" />
                                <joint name="wrist_1_joint" class="UR3e" pos="0 0 0" axis="0 1 0" limited="true" range="-6.28319 6.28319" />
                                <geom type="mesh"  mesh="wrist1" class="visual_arm"/>
                                <body name="wrist_2_link" pos="0 0.08505 0">
                                    <inertial pos="0 0 0" quat="0.5 0.5 -0.5 0.5" mass="0.8" diaginertia="0.00225 0.002085 0.002085" />
                                    <joint name="wrist_2_joint" axis="0 0 1" class="size1"/>
                                    <geom material="black" class="visual_arm" type="mesh"  mesh="wrist2" />
                                    <body name="wrist_3_link" pos="0 0 0.08535">
                                        <inertial pos="0 0 0" quat="0.5 0.5 -0.5 0.5" mass="0.35" diaginertia="0.000984375 0.000912187 0.000912187" />
                                        <joint name="wrist_3_joint" class="size1" axis="0 1 0" />
                                        <geom class="visual_arm" name="wrist_3_link" type="mesh"  mesh="wrist3" material="linkgray"/>
                                        <!--GRIPPER-->
                                        <body name="base_mount" pos="0 0.0819 -0.002" quat="0.707107 -0.707107 0 0" childclass="2f85">
                                            <geom class="visual" mesh="base_mount" material="black"/>
                                            <geom class="collision" mesh="base_mount"/>
                                            <site name="ee_site" pos="0 0 0.06" size="0.005 0.005 0.005" type="sphere" rgba="0.3 0.2 0.1 1"/>

                                              <body name="cylinder_obj" pos="0 0 0.15">
                                                    <geom class="collision_tool" />

                                                    <geom class="visual_tool" rgba="1 0.5 0.5 1" />
                                                    <joint class="tool_ball_joint" />
                                                    <body name="cylinder_obj1" pos="0 0 0.005">
                                                        <geom class="collision_tool" />
                                                        <geom class="visual_tool" rgba="0 0.5 0.5 1" />
                                                        <joint class="tool_ball_joint" />
                                                        <body name="cylinder_obj2" pos="0 0 0.005">
                                                            <geom class="collision_tool" />
                                                            <geom class="visual_tool" rgba="0 0.5 0.5 1" />
                                                            <joint class="tool_ball_joint" />
                                                            <body name="cylinder_obj3" pos="0 0 0.005">
                                                                <geom class="collision_tool" />
                                                                <geom class="visual_tool" rgba="0 0.5 0.5 1" />
                                                                <joint class="tool_ball_joint" />
                                                                <body name="cylinder_obj4" pos="0 0 0.005">
                                                                    <geom class="collision_tool" />
                                                                    <geom class="visual_tool" rgba="0 0.5 0.5 1" />
                                                                    <joint class="tool_ball_joint" />
                                                                    <body name="cylinder_obj5" pos="0 0 0.005">
                                                                        <geom class="collision_tool" />
                                                                        <geom class="visual_tool" rgba="0 0.5 0.5 1" />
                                                                        <joint class="tool_ball_joint" />
                                                                        <body name="cylinder_obj6" pos="0 0 0.005">
                                                                            <geom class="collision_tool" />
                                                                            <geom class="visual_tool" rgba="0 0.5 0.5 1" />
                                                                            <joint class="tool_ball_joint" />
                                                                            <body name="cylinder_obj7" pos="0 0 0.005">
                                                                                <geom class="collision_tool" />
                                                                                <geom class="visual_tool" rgba="0 0.5 0.5 1" />
                                                                                <joint class="tool_ball_joint" />
                                                                                <body name="cylinder_obj8" pos="0 0 0.005">
                                                                                    <geom class="collision_tool" />
                                                                                    <geom class="visual_tool" rgba="0 0.5 0.5 1" />
                                                                                    <joint class="tool_ball_joint" />
                                                                                    <body name="cylinder_obj9" pos="0 0 0.005">
                                                                                        <geom class="collision_tool" />
                                                                                        <geom class="visual_tool" rgba="0 0.5 0.5 1" />
                                                                                        <joint class="tool_ball_joint" />
                                                                                        <body name="cylinder_obj10" pos="0 0 0.005">
                                                                                            <geom class="collision_tool" />
                                                                                            <geom class="visual_tool" rgba="0 0.5 0.5 1" />
                                                                                            <joint class="tool_ball_joint" />
                                                                                            <body name="cylinder_obj11" pos="0 0 0.005">
                                                                                                <geom class="collision_tool" />
                                                                                                <geom class="visual_tool" rgba="0 0.5 0.5 1" />
                                                                                                <joint class="tool_ball_joint" />
                                                                                                <body name="cylinder_obj12" pos="0 0 0.005">
                                                                                                    <geom class="collision_tool" />
                                                                                                    <geom class="visual_tool" rgba="0 0.5 0.5 1" />
                                                                                                    <joint class="tool_ball_joint" />
                                                                                                    <body name="cylinder_obj13" pos="0 0 0.005">
                                                                                                        <geom class="collision_tool" />
                                                                                                        <geom class="visual_tool" rgba="0 0.5 0.5 1" />
                                                                                                        <joint class="tool_ball_joint" />
                                                                                                        <body name="cylinder_obj14" pos="0 0 0.005">
                                                                                                            <geom class="collision_tool" />
                                                                                                            <geom class="visual_tool" rgba="0 0.5 0.5 1" />
                                                                                                            <joint class="tool_ball_joint" />
                                                                                                            <body name="cylinder_obj15" pos="0 0 0.005">
                                                                                                                <geom class="collision_tool" />
                                                                                                                <geom class="visual_tool" rgba="0 0.5 0.5 1" />

                                                                                                                <site name="obj_bottom" type="sphere" size=".001 .001 .001" pos="0 0 0" quat="1 0 0 0" />
                                                                                                            </body>
                                                                                                        </body>
                                                                                                    </body>
                                                                                                </body>
                                                                                            </body>
                                                                                        </body>
                                                                                    </body>
                                                                                </body>
                                                                            </body>
                                                                        </body>
                                                                    </body>
                                                                </body>
                                                            </body>
                                                        </body>
                                                    </body>
                                              </body>
                      </body>
                    </body>
                  </body>
                </body>
              </body>
            </body>
          </body>
        </body>
      </body>
  </worldbody>

    <actuator>
        <position class="size3" name="shoulder_pan" joint="shoulder_pan_joint" />
        <position class="size3" name="shoulder_lift" joint="shoulder_lift_joint" />
        <position class="size3_limited" name="elbow" joint="elbow_joint" />
        <position class="size1" name="wrist_1" joint="wrist_1_joint" />
        <position class="size1" name="wrist_2" joint="wrist_2_joint" />
        <position class="size1" name="wrist_3" joint="wrist_3_joint" />

    </actuator>
    <contact>


        <exclude body1="cylinder_obj" body2="cylinder_obj1" />
        <exclude body1="cylinder_obj1" body2="cylinder_obj2" />
        <exclude body1="cylinder_obj3" body2="cylinder_obj2" />
        <exclude body1="cylinder_obj3" body2="cylinder_obj4" />
        <exclude body1="cylinder_obj5" body2="cylinder_obj4" />
        <exclude body1="cylinder_obj5" body2="cylinder_obj6" />
        <exclude body1="cylinder_obj7" body2="cylinder_obj6" />
        <exclude body1="cylinder_obj7" body2="cylinder_obj8" />
        <exclude body1="cylinder_obj9" body2="cylinder_obj8" />
        <exclude body1="cylinder_obj10" body2="cylinder_obj10" />
        <exclude body1="cylinder_obj11" body2="cylinder_obj10" />
        <exclude body1="cylinder_obj11" body2="cylinder_obj12" />
        <exclude body1="cylinder_obj13" body2="cylinder_obj12" />
        <exclude body1="cylinder_obj13" body2="cylinder_obj14" />
        <exclude body1="cylinder_obj15" body2="cylinder_obj14" />

    </contact>


    <sensor>
        <force name="ee_force_sensor" site="ee_site" />
        <torque name="ee_torque_sensor" site="ee_site" />
    </sensor>




</mujoco>