<!--

MODEL: Univewrsal Robots UR3 + Robotiq 2F-85
AUTHOR: Yi Liu @AiRO 
UNIVERSITY: UGent-imec
DEPARTMENT: Faculty of Engineering and Architecture
Control Engineering / Automation Engineering

-->

<mujoco model="ur3gripper">

    <option timestep="2e-3"
            iterations="10"
            tolerance="1e-5"
            impratio="20"/>
    
    <compiler angle="radian" 
              inertiafromgeom="true"
              texturedir="textures/"
              meshdir="meshs/visual/"/>
    <size njmax="10000" nconmax="1500" nstack="3000000"/>


    <default>
        <site rgba="0.8 0.6 0.7 0.3" type="ellipsoid" group="3"/>
        <geom contype='1' conaffinity='1' condim='6'  margin="1e-3" solref=".01 1" solimp=".99 .99 .01" />
        <joint armature="0.01" damping=".1"/>
        <default class="UR3">
            <joint damping='65'/>
        </default>
        <default class="UR3e">
            <joint damping='45'/>
        </default>
        <default class="GRIPPER">
            <joint damping='5'/>
        </default>
        <camera mode="fixed" pos="10 -2 2.7" axisangle="5 8 0 0.9"/>
    </default>

    <visual>
        <map fogstart="3" fogend="5" znear="0.05"/>
        <quality shadowsize="2048"/> 
        <scale framelength="0.1"
               framewidth="0.005"
               contactwidth="0.1"
               contactheight="0.005"
               forcewidth="0.01"
               />
	<global  fovy="45"  />
    </visual>

    <asset>
        <mesh name="base" file="base.stl" />
        <mesh name="shoulder" file="shoulder.stl" />
        <mesh name="upperarm" file="upperarm.stl" />
        <mesh name="forearm" file="forearm.stl" />
        <mesh name="wrist1" file="wrist1.stl" />
        <mesh name="wrist2" file="wrist2.stl" />
        <mesh name="wrist3" file="wrist3.stl" />
        <mesh name="gripperconnector" file="kinova_robotiq_coupler.stl" />
        <mesh name="gripperpalm" file="robotiq_85_base_link.stl" />
        <mesh name="link_0" file="robotiq_85_finger_link.stl" />
        <mesh name="link_1" file="robotiq_85_finger_tip_link.stl" />
        <mesh name="link_2" file="robotiq_85_inner_knuckle_link.stl" />
        <mesh name="link_3" file="robotiq_85_knuckle_link.stl" />
        <mesh name="finger" file="finger_tip_.stl" />
        <mesh name="fingertip" file="fingertip_test.stl" />
        <mesh name="_hole" file="triangle_hole_1mm.stl" />
        <mesh name="_obj" file="triangle_obj.stl" />
        <mesh name="triangle_obj" file="triangleforPrinter.stl" />
        <mesh name="_hole1" file="triangle_hole1.stl" />
        <mesh name="_hole2" file="triangle_hole2.stl" />
        <mesh name="_hole3" file="triangle_hole3.stl" />

        <mesh name="BOX"   file="BOX.stl"/>
        <mesh file="AllFinal_hull_1.stl" name="1"  scale="1.2 1.2 0.8"/>
        <mesh file="AllFinal_hull_2.stl" name="2" scale="1.2 1.2 0.8" />
        <mesh file="AllFinal_hull_3.stl" name="3" scale="1.2 1.2 0.8" />
        <mesh file="AllFinal_hull_4.stl" name="4" scale="1.2 1.2 0.8" />
        <mesh file="AllFinal_hull_5.stl" name="5" scale="1.2 1.2 0.8 "/>
        <mesh file="AllFinal_hull_6.stl" name="6" scale="1.2 1.2 0.8" />
        <mesh file="AllFinal_hull_7.stl" name="7"  scale="1.2 1.2 0.8"/>
        <mesh file="AllFinal_hull_8.stl" name="8"  scale="1.2 1.2 0.8"/>
        <mesh file="AllFinal_hull_9.stl" name="9" scale="1.2 1.2 0.8" />
        <mesh file="AllFinal_hull_10.stl" name="10"  scale="1.2 1.2 0.8"/>
        <mesh file="AllFinal_hull_11.stl" name="11"  scale="1.2 1.2 0.8"/>
        <mesh file="AllFinal_hull_12.stl" name="12"  scale="1.2 1.2 0.8" />

        <!--Textures-->
        <texture name="ur3_tex"     type="2d"       builtin="flat" height="32" width="32" rgb1="0.45 0.45 0.45" />
        <texture name="gripper_tex" type="2d"       builtin="flat" height="32" width="32" rgb1="0.45 0.45 0.45" rgb2="0 0 0"/>
        <texture name="bench_tex"   type="2d"       builtin="flat" height="32" width="32" rgb1="0.7 0.7 0.7" />
        <texture name="sky_tex"     type="skybox"   builtin="gradient" width="100" height="100" rgb1="1 1 1" rgb2="0.3 0.3 0.8" />
        <texture name="texgeom"     type="cube"     builtin="flat" mark="cross" width="127" height="1278" rgb1="0.8 0.6 0.4" rgb2="0.8 0.6 0.4" markrgb="1 1 1" random="0.01" />
        <texture name="floor_tex"   type="2d"        builtin="checker" rgb1=".2 .3 .4" rgb2=".1 .2 .3" width="100" height="100" />
        <texture name="wood"        type="cube"     file="wood2.png"/>
        <texture name="metal1"      type="cube"     file="metal2.png"/>
        <!--Materials-->
        <material name="ur3_mat"        texture="ur3_tex"   shininess="0.9" specular="0.75" reflectance="0.3"/>
        <material name="gripper_mat"    texture="gripper_tex"   shininess="0.9" specular="0.75" reflectance="0.4"/>
        <material name='floor_mat'      texture="floor_tex"  shininess="0.8" texrepeat="10 10" specular="0.7"  reflectance="0.5" />
        <material name='geom'           texture="texgeom"   texuniform="true" />
        <material name="bench_mat"      texture="metal1"   shininess="0.1" specular="0.5" reflectance="0.2"/>
        <material name="tablecube"      texture="wood" rgba=".8 .8 .8 1"/>
   	    <material name="metal_box" reflectance="0.5" texrepeat="1 1" texture="metal1" texuniform="true"/>
        
        <material name="GriMat" specular="0.9" shininess="0.5" reflectance="0" rgba="0.1 0.1 0.1 1" emission="0.1" />
        <material name="FingerMat" specular="0.9" shininess="0.5" reflectance="0" rgba="0.5 0.5 0.1 1" emission="0.1" />
        <material name="BasketMat" specular="0" shininess="0" reflectance="0" rgba="0.26 0.16 0.16796875 1" emission="0" />
        <material name="Light" specular="0" shininess="0.6" reflectance="0.9" rgba="0.5 0.5 1 1" emission="0.7" />

    </asset>

    <contact>
        <exclude body1="OUR_TABLE" body2="base_link"/>
        <exclude body1="base_link" body2="shoulder_link"/>
        <exclude body1="shoulder_link" body2="upper_arm_link"/>
        <exclude body1="upper_arm_link" body2="forearm_link"/>
        <exclude body1="forearm_link" body2="wrist_1_link"/>
        <exclude body1="wrist_1_link" body2="wrist_2_link"/>
        <exclude body1="wrist_2_link" body2="wrist_3_link"/>
        <exclude body1="ee_link" body2="wrist_3_link"/>
    </contact>

    <worldbody>
            <!--Lighting parameters-->
        <light name="light3" mode="targetbody" target="OUR_TABLE" directional="true" pos="1 -1 3" />
        <!--Camera parameters-->
        <camera name="main1" mode="trackcom" target="OUR_TABLE" pos="0 1.2 2" axisangle="0 0.5 1 3.1415927"/>
        <!--Floor Property-->
        <geom name='floor' material="floor_mat" pos='0 0 0' size='2.5 2.5 0.1'  type='plane' />
	
        
        <!-- <body name="OBJ_TABLE" pos="0 0.5 0.435">
            <geom size=".6 .3 .03" pos ="0 0 0.4" type="box" material="bench_mat"/>
            <geom size=".6 .3 .03" pos ="0 0 -0.2" type="box" material="bench_mat"/>
            <geom size=".04 .04 .435" pos =".57 .27 0" type="box" material="bench_mat"/>
            <geom size=".04 .04 .435" pos ="-.57 .27 0" type="box" material="bench_mat"/>
            <geom size=".04 .04 .435" pos =".57 -.27 0" type="box" material="bench_mat"/>
            <geom size=".04 .04 .435" pos ="-.57 -.27 0" type="box" material="bench_mat"/>
            <inertial pos="0 0 0" mass="1000" diaginertia="0 0 0" />
        </body> -->
       
        <!-- <body name="box" pos="0 0.35 0.915">
        	<geom name="box_hole" pos="0 0 0" mesh="box_hole" type="mesh" solimp="0.998 0.998 0.001" solref="0.001 1" density="6700" rgba="0 1 0 1"  />
        </body> -->
        <!-- <body mocap="true" name="box" pos="0 0.35 0.935">
            <body name="object">
                <geom pos="-0.11 0 0" size="0.06 0.17 0.02" type="box" group="0" material="bench_mat" />
                <geom pos="0.11 0 0" size="0.06 0.17 0.02" type="box" group="0" material="bench_mat" />
                <geom pos="0 0.11 0" size="0.05 0.06 0.02" type="box" group="0" material="bench_mat" />
                <geom pos="0 -0.11 0" size="0.05 0.06 0.02" type="box" group="0" material="bench_mat" />
            </body>
        </body> -->

        <!-- -0.38 0.3 0.885 --> 
        <!-- 0.38 0.38 0.955 -->
        <!-- limit -->
    
        <!-- -0.15 0.34 .885 -->
        <!-- side length err 1mm -->
        <!-- <body mocap="true" name="box" pos="0.1 0.4 0.9"> 
            <body name="object">
                <geom type="mesh"  mesh="_hole1" material="bench_mat"/>
                <geom type="mesh"  mesh="_hole2" material="bench_mat"/>
                <geom type="mesh"  mesh="_hole3" material="bench_mat"/>
                <site name="box_surface" pos="0 0 0.02" size="0.001 0.001 0.001" type="sphere" rgba="0.3 0.2 0.1 1"/>
            </body>
        </body> -->

        <!-- side length err 4mm -->
        <!-- <body mocap="true" name="box" pos="0.1 0.4 0.9"> 
            <body name="object">
                <geom pos="0 -0.003 0" type="mesh"  mesh="_hole1" material="bench_mat"/>
                <geom pos="0.003434 0.003 0" type="mesh"  mesh="_hole2" material="bench_mat"/>
                <geom pos="-0.003434 0.003 0" type="mesh"  mesh="_hole3" material="bench_mat"/>
                <site name="box_surface" pos="0 0 0.02" size="0.001 0.001 0.001" type="sphere" rgba="0.3 0.2 0.1 1"/>
            </body>
        </body> -->
        
        <!-- side length err 1cm -->
        <body mocap="true" name="box" pos="0.1 0.4 0.9"> 
            <body name="object">
                <geom pos="0 0.004 0" type="mesh"  mesh="_hole1" material="bench_mat" rgba="0.6 0.2 0.1 1"/>
                <geom pos="-0.0035 -0.0035 0" type="mesh"  mesh="_hole2" material="bench_mat" rgba="0.6 0.2 0.1 1"/>
                <geom pos="0.0035 -0.0035  0" type="mesh"  mesh="_hole3" material="bench_mat"rgba="0.6 0.2 0.1 1"/>
                <site name="box_surface" pos="0 0 0.02" size="0.001 0.001 0.001" type="sphere" rgba="0.3 0.2 0.1 1"/>
            </body>
        </body>

        
<!-- -0.11235115  0.29859969  1.0047236 -->
        <!-- <body mocap="true" name="target_ball" pos="0.05 0.38 0.985" quat="1 0 0 0">
            <body name="ball">
                <geom name="cylinder2" type="box" size=".005 .005 .004"  euler="0 0 0" rgba="0 0.5 0.5 1" material="gripper_mat" contype="0" conaffinity="1"/>
            </body>
        </body> -->

        <!--Robot UR3-->
        <body name="OUR_TABLE" pos="0 0 0.435">
            <!--<geom size=".3 .2 .435" type="box" material="bench_mat"/>-->
            <geom size=".69 .19 .03" pos ="0 0 0.4" type="box" material="bench_mat"/>
            <geom size=".69 .19 .03" pos ="0 0 -0.2" type="box" material="bench_mat"/>
            <geom size=".04 .04 .435" pos =".66 .16 0" type="box" material="bench_mat"/>
            <geom size=".04 .04 .435" pos ="-.66 .16 0" type="box" material="bench_mat"/>
            <geom size=".04 .04 .435" pos =".66 -.16 0" type="box" material="bench_mat"/>
            <geom size=".04 .04 .435" pos ="-.66 -.16 0" type="box" material="bench_mat"/>
            <inertial pos="0 0 0" mass="1000" diaginertia="0 0 0" />
        
            <body name="base_link" pos="0 0 0.425">
                <inertial pos="0 0 0" quat="0.5 0.5 -0.5 0.5" mass="5" diaginertia="0.005625 0.00305317 0.00305317" />
                <geom type="mesh"  mesh="base" material="ur3_mat"/>
                <body name="shoulder_link" pos="0 0 0.1530">
                    <inertial pos="0 0 0" mass="3" diaginertia="0.00809316 0.00809316 0.005625" />
                    <joint name="shoulder_pan_joint" class="UR3" pos="0 0 0" axis="0 0 1" limited="true" range="-3.14159 3.14159" />
                    <geom type="mesh"  mesh="shoulder" material="ur3_mat"/>
                    <body name="upper_arm_link" pos="0 0.1198 0" quat="0.707107 0 0.707107 0">
                        <inertial pos="0 0 0.121825" mass="3.42" diaginertia="0.0217285 0.0217285 0.00961875" />
                        <joint name="shoulder_lift_joint" class="UR3" pos="0 0 0" axis="0 1 0" limited="true" range="-3.14159 3.14159" />
                        <geom type="mesh"  mesh="upperarm" material="ur3_mat"/>
                        <body name="forearm_link" pos="0 -0.0925 0.24365">
                            <inertial pos="0 0 0.106625" mass="1.26" diaginertia="0.00654681 0.00654681 0.00354375" />
                            <joint name="elbow_joint" class="UR3" pos="0 0 0" axis="0 1 0" limited="true" range="-3.14159 3.14159" />
                            <geom type="mesh"  mesh="forearm" material="ur3_mat"/>
                            <body name="wrist_1_link" pos="0 0 0.21325" quat="0.707107 0 0.707107 0">
                                <inertial pos="0 0 0" quat="0.5 0.5 -0.5 0.5" mass="0.8" diaginertia="0.00225 0.002085 0.002085" />
                                <joint name="wrist_1_joint" class="UR3e" pos="0 0 0" axis="0 1 0" limited="true" range="-6.28319 6.28319" />
                                <geom type="mesh"  mesh="wrist1" material="ur3_mat"/>
                                <body name="wrist_2_link" pos="0 0.08505 0">
                                    <inertial pos="0 0 0" quat="0.5 0.5 -0.5 0.5" mass="0.8" diaginertia="0.00225 0.002085 0.002085" />
                                    <joint name="wrist_2_joint" class="UR3e" pos="0 0 0" axis="0 0 1" limited="true" range="-6.28319 6.28319" />
                                    <geom type="mesh"  mesh="wrist2" material="ur3_mat"/>
                                    <body name="wrist_3_link" pos="0 0 0.08535">
                                        <inertial pos="0 0 0" quat="0.5 0.5 -0.5 0.5" mass="0.35" diaginertia="0.000984375 0.000912187 0.000912187" />
                                        <joint name="wrist_3_joint" class="UR3e" pos="0 0 0" axis="0 1 0" limited="true" range="-6.28319 6.28319" />
                                        <geom name="wrist_3_link" type="mesh"  mesh="wrist3" material="ur3_mat" rgba="1 0 0 1"/>
                                        <!--GRIPPER-->
                                        <body name="ee_link" pos="0 0.0819 0" quat="0.707107 -0.707107 0 0">
                                            <inertial pos="-0.01 0 0" mass="0.001" diaginertia="1.66667e-08 1.66667e-08 1.66667e-08" />
                                            <geom size="0.005 0.005 0.005" pos="-0.01 0 0" type="box" />
                                            <geom name="light_1" type="sphere" size="0.005" pos="0.035 0 0.0166" material="Light" />
                                            <geom name="light_2" type="sphere" size="0.005" pos="-0.035 0 0.0166" material="Light" />
                                            <geom name="gripperconnector" type="mesh" mesh="gripperconnector" pos="0 0 0.0466" material="GriMat" />
                                            <geom name="gripperpalm" type="mesh" mesh="gripperpalm" pos="0 0 0.0016" quat="0.707107 0 -0.707107 0" material="GriMat" />
                                            <site name="ee_site" pos="0 0.06 0" size="0.005 0.005 0.005" type="sphere" rgba="0.3 0.2 0.1 1"/>
                                            <body name="right_driver" pos="0 -0.0306011 0.054904" quat="0.707107 0 -0.707107 0">
                                                <geom name="right_driver_mesh" type="mesh" mesh="link_3" material="GriMat" contype="0" conaffinity="0" />
                                                <joint name="right_driver_1" damping="1"  axis="0 0 1" type="hinge" limited="true" range="-0.1 0.8" />
                                                <body name="right_coupler" pos="0 -0.0315 0">
                                                    <geom name="right_coupler_mesh" type="mesh" mesh="link_0" material="GriMat" contype="0" conaffinity="0" />
                                                    <joint name="right_driver_2" damping="1" axis="0 0 1" type="hinge" limited="true" range="-0.01 0.8" />
                                                    <body name="right_follower_link" pos="0.0475 -0.006 0">
                                                        <geom name="right_follower_mesh" pos="0.0025 0.021 0" type="mesh" mesh="link_1" material="GriMat" />
                                                        <joint name="right_driver_3" damping="1"  axis="0 0 1" type="hinge" limited="true" range="-0.8 0.01" />
                                                    </body>
                                                </body>
                                            </body>
                                            <body name="right_spring_link" pos="0.0016 -0.012 0.0614" quat="0.707107 0 -0.707107 0">
                                                <geom name="right_spring_mesh" type="mesh" pos="0 -0.0005 0.0016" mesh="link_2" material="GriMat" contype="0" conaffinity="0" />
                                                <joint name="right_driver_4" damping="0.1" axis="0 0 1" type="hinge" limited="true" range="-0.01 0.8" />
                                            </body>
                                            <body name="left_driver" pos="0 0.0306011 0.054904" quat="0 0.707107 0 0.707107">
                                                <geom name="left_driver_mesh" type="mesh" mesh="link_3" material="GriMat" contype="0" conaffinity="0" />
                                                <joint name="left_driver_1" damping="1"  axis="0 0 1" type="hinge" limited="true" range="-0.1 0.8" />
                                                <body name="left_coupler" pos="0 -0.0315 0">
                                                    <geom name="left_coupler_mesh" type="mesh" mesh="link_0" material="GriMat" contype="0" conaffinity="0" />
                                                    <joint name="left_driver_2" damping="1"  axis="0 0 1" type="hinge" limited="true" range="-0.01 0.01" />
                                                    <body name="left_follower_link" pos="0.0475 -0.006 0">
                                                        <geom name="left_follower_mesh" pos="0.0025 0.021 0" type="mesh" mesh="link_1" material="GriMat" />
                                                        <joint name="left_driver_3" damping="1"  axis="0 0 1" type="hinge" limited="true" range="-0.8 0.01" />
                                                    </body>
                                                </body>
                                            </body>
                                            <body name="left_spring_link" pos="0.0016 0.012 0.0614" quat="0 0.707107 0 0.707107">
                                                <geom name="left_spring_mesh" type="mesh" pos="0 0.0005 0.0016" mesh="link_2" material="GriMat" contype="0" conaffinity="0" />
                                                <joint name="left_driver_4" damping="0.1" axis="0 0 1" type="hinge" limited="true" range="-0.01 0.8" />
                                            </body>
                                            <body name="eef" pos="0 0 0.18">
                                                <!-- <geom type="mesh" mesh="fingertip" rgba="0 0.9 0 1" /> -->
                                                <site name="ee_tool" pos="0 0 0" size="1 1 1" type="box" rgba="0.3 0.2 0.1 1"/>
                                            </body>
                                            <body name="cylinder_obj" pos="0 0 0.18" quat="0 1 0 0">
                                                <!-- <joint type="slide" pos="0 0 0" stiffness="500" axis="0 0 1" damping="20" limited="true" range="-0.0001 0"/> -->
                                                <!-- <joint pos="0 0 0" stiffness="10" axis="0 -1 0" damping="2" limited="true" range="-0.7 0.7"/> -->
                                                <geom name="cylinder22" type="mesh" pos="0 0 0" mesh="triangle_obj" contype="1" conaffinity="0"/>
                                                <!-- <geom name="cylinder1" pos="0 0 0.01" friction="0.5" type="box" size=".015 .015 .06"  euler="0 0 0" rgba="0 0.5 0.5 1" material="gripper_mat" contype="1" conaffinity="0"/> -->
                                                <site name="obj_bottom" pos="0 0 -0.02" size="0.001 0.001 0.001" type="sphere" rgba="0.3 0.2 0.1 1"/>
                                            </body>
                                        </body>
                                    </body>
                                </body>
                            </body>
                        </body>
                    </body>
                </body>
                <body name="base" pos="0 0 0" quat="0 0 0 -1">
                    <inertial pos="0 0 0" quat="1.7949e-09 0 0 -1" mass="0" diaginertia="0 0 0" />
                </body>
            </body>
        </body>	
        
        

    </worldbody>

    <equality>
        <connect body1="right_follower_link" body2="right_coupler" anchor="0 0 0" solref="0.01 0.5" active="true"/>
        <connect body1="right_follower_link" body2="right_spring_link" anchor="0.0054 0.0192 0" solref="0.01 0.5" active="true"/>
		<connect body1="right_driver" body2="right_coupler" anchor="0 0 0" solref="0.01 0.5" active="true"/>

        <connect body1="left_follower_link" body2="left_coupler" anchor="0 0 0" solref="0.01 0.5" active="true"/>
        <connect body1="left_follower_link" body2="left_spring_link" anchor="0.0054 0.0192 0" solref="0.01 0.5" active="true"/>
        <connect body1="left_driver" body2="left_coupler" anchor="0 0 0" solref="0.01 0.5" active="true"/>

        <joint name="symmetry:control" joint1="right_driver_1" joint2="left_driver_1" polycoef="0 1 0 0 0"/>
	</equality>

    <actuator>
        <position name='shoulder_pan' ctrllimited="true" ctrlrange="-3.14159 3.14159" joint='shoulder_pan_joint' kp="3000"/>
        <position name='shoulder_lift' ctrllimited="true" ctrlrange="-3.14159 3.14159" joint='shoulder_lift_joint' kp="3000"/>
        <position name='forearm' ctrllimited="true" ctrlrange="-3.14159 3.14159" joint='elbow_joint' kp="3000"/>
        <position name='wrist_1' ctrllimited="true" ctrlrange="-3.14159 3.14159" joint='wrist_1_joint' kp="3000"/>
        <position name='wrist_2' ctrllimited="true" ctrlrange="-3.14159 3.14159" joint='wrist_2_joint' kp="3000"/>
        <position name='wrist_3' ctrllimited="true" ctrlrange="-3.14159 3.14159" joint='wrist_3_joint' kp="3000"/>

        <!-- <motor name='shoulder_pan_T' ctrllimited="true" ctrlrange="-2 2" joint='shoulder_pan_joint' gear="101"/> 
        <motor name='shoulder_lift_T' ctrllimited="true" ctrlrange="-2 2" joint='shoulder_lift_joint' gear="101"/>
        <motor name='forearm_T' ctrllimited="true" ctrlrange="-2 2" joint='elbow_joint' gear="101" />
        <motor name='wrist_1_T' ctrllimited="true" ctrlrange="-1 1" joint='wrist_1_joint' gear="101"/> 
        <motor name='wrist_2_T' ctrllimited="true" ctrlrange="-1 1" joint='wrist_2_joint' gear="101"/>
        <motor name='wrist_3_T' ctrllimited="true" ctrlrange="-1 1" joint='wrist_3_joint' gear="101"/> -->

        <!--<velocity name='shoulder_pan_v' class="UR5" joint='shoulder_pan_joint' kv="10"/>
        <velocity name='shoulder_lift_v' class="UR5" joint='shoulder_lift_joint' />
        <velocity name='forearm_v' class="UR5" joint='elbow_joint' />
        <velocity name='wrist_1_v' class="UR5" joint='wrist_1_joint' />
        <velocity name='wrist_2_v' class="UR5" joint='wrist_2_joint'/>
        <velocity name='wrist_3_v' class="UR5" joint='wrist_3_joint'/>-->

        <!--Gripper-->
        <position name='grippercontrol' ctrllimited="true" kp="30" joint='left_driver_1' ctrlrange='0 0.65' />
        <!-- <position name="close_r" joint="right_driver_1" ctrllimited="true" ctrlrange="-1 1" kp="3"/> -->
        <!-- <position name="close_l" joint="left_driver_1" ctrllimited="true" ctrlrange="-1 1" kp="3"/> -->
        <!-- <position name='finger_1' ctrllimited="true" kp="20" joint='right_driver_1' ctrlrange='0 1.2217'/>
        <position name='finger_2' ctrllimited="true" kp="20" joint='left_driver_1' ctrlrange='0 1.2217'/> -->
        <!-- <position name='finger_scissor' ctrllimited="true" kp="20" joint='gripperpalm_finger_1_joint' ctrlrange="-0.2967 0.2967"/> -->

        <!-- <motor name='finger_1_T' ctrllimited="true" joint='gripperfinger_1_joint_1' ctrlrange='-0.1 .8' gear="20"/>
        <motor name='finger_2_T' ctrllimited="true" joint='gripperfinger_2_joint_1' ctrlrange='-0.1 .8' gear="20"/>
        <motor name='finger_scissor_T' ctrllimited="true" joint='gripperpalm_finger_1_joint' ctrlrange="-0.8 0.8" gear="15"/> -->
    </actuator>
    <sensor>
        <!-- <touch name="touchsensor_r1" site="right_touch_sensor1" />
        <touch name="touchsensor_r2" site="right_touch_sensor2" />
        <touch name="touchsensor_r3" site="right_touch_sensor3" />
        <touch name="touchsensor_r4" site="right_touch_sensor4" />
        <touch name="touchsensor_r5" site="right_touch_sensor5" />
        <touch name="touchsensor_r6" site="right_touch_sensor6" />
        <touch name="touchsensor_l1" site="left_touch_sensor1" />
        <touch name="touchsensor_l2" site="left_touch_sensor2" />
        <touch name="touchsensor_l3" site="left_touch_sensor3" />
        <touch name="touchsensor_l4" site="left_touch_sensor4" />
        <touch name="touchsensor_l5" site="left_touch_sensor5" />
        <touch name="touchsensor_l6" site="left_touch_sensor6" /> -->
        <force name="ee_force_sensor" site="ee_site"/>
        <torque name="ee_torque_sensor" site="ee_site"/>
    </sensor>
</mujoco>
